<?xml version="1.0" ?>
<!-- =================================================================================== -->
<!-- |    This document was autogenerated by xacro from irb6620.urdf.xacro             | -->
<!-- |    EDITING THIS FILE BY HAND IS NOT RECOMMENDED                                 | -->
<!-- =================================================================================== -->
<robot name="irb6620">
  <!-- Robot description -->
  <!-- <xacro:include filename="$(find abb_irb6620_support)/urdf/materials.xacro" /> -->
  <!-- <xacro:include filename="$(find abb_irb6620_support)/urdf/irb6620.trans" /> -->
  <link name="base_link">
    <inertial>
      <origin rpy="0 0 0" xyz="-0.132426271542629 0.00025747943822749576 0.10729619546582686"/>
      <mass value="776.9359106593752"/>
      <inertia ixx="25.729826" ixy="-0.030919" ixz="0.51906" iyy="53.397553" iyz="-0.078877" izz="73.957156"/>
    </inertial>
    <visual>
      <origin rpy="0 0 0" xyz="0 0 0"/>
      <geometry>
        <mesh filename="package://abb_irb6620_support/meshes/base_link.stl" scale="0.001 0.001 0.001"/>
      </geometry>
      <material name="opaque215215215"/>
    </visual>
    <collision>
      <origin rpy="0 0 0" xyz="0 0 0"/>
      <geometry>
        <mesh filename="package://abb_irb6620_support/meshes/base_link.stl" scale="0.001 0.001 0.001"/>
      </geometry>
    </collision>
  </link>
  <link name="link2_1">
    <inertial>
      <origin rpy="0 0 0" xyz="0.0005479770874909917 -0.08783951896438288 0.4192832792190023"/>
      <mass value="322.6869494051032"/>
      <inertia ixx="31.332255" ixy="0.002905" ixz="-0.067522" iyy="32.058389" iyz="2.969817" izz="2.725277"/>
    </inertial>
    <visual>
      <origin rpy="0 0 0" xyz="-0.32 0.1305 -0.68"/>
      <geometry>
        <mesh filename="package://abb_irb6620_support/meshes/link2_1.stl" scale="0.001 0.001 0.001"/>
      </geometry>
      <material name="opaque215215215"/>
    </visual>
    <collision>
      <origin rpy="0 0 0" xyz="-0.32 0.1305 -0.68"/>
      <geometry>
        <mesh filename="package://abb_irb6620_support/meshes/link2_1.stl" scale="0.001 0.001 0.001"/>
      </geometry>
    </collision>
  </link>
  <link name="link3_1">
    <inertial>
      <origin rpy="0 0 0" xyz="-0.04789961325357317 0.23437540848823246 0.11779163280818872"/>
      <mass value="392.46903681876654"/>
      <inertia ixx="11.726762" ixy="1.465206" ixz="1.592788" iyy="10.861718" iyz="-2.045934" izz="11.751196"/>
    </inertial>
    <visual>
      <origin rpy="0 0 0" xyz="-0.32 0.226 -1.655"/>
      <geometry>
        <mesh filename="package://abb_irb6620_support/meshes/link3_1.stl" scale="0.001 0.001 0.001"/>
      </geometry>
      <material name="opaque215215215"/>
    </visual>
    <collision>
      <origin rpy="0 0 0" xyz="-0.32 0.226 -1.655"/>
      <geometry>
        <mesh filename="package://abb_irb6620_support/meshes/link3_1.stl" scale="0.001 0.001 0.001"/>
      </geometry>
    </collision>
  </link>
  <link name="link4_1">
    <inertial>
      <origin rpy="0 0 0" xyz="0.39206968327914915 -0.014153009406367673 -6.0809943929651666e-05"/>
      <mass value="283.78132224866226"/>
      <inertia ixx="3.961577" ixy="0.662055" ixz="-0.007475" iyy="11.46404" iyz="0.000528" izz="13.570946"/>
    </inertial>
    <visual>
      <origin rpy="0 0 0" xyz="-0.502 -0.0 -1.855"/>
      <geometry>
        <mesh filename="package://abb_irb6620_support/meshes/link4_1.stl" scale="0.001 0.001 0.001"/>
      </geometry>
      <material name="opaque215215215"/>
    </visual>
    <collision>
      <origin rpy="0 0 0" xyz="-0.502 -0.0 -1.855"/>
      <geometry>
        <mesh filename="package://abb_irb6620_support/meshes/link4_1.stl" scale="0.001 0.001 0.001"/>
      </geometry>
    </collision>
  </link>
  <link name="link5_1">
    <inertial>
      <origin rpy="0 0 0" xyz="0.03807418429508913 -0.10016333880680821 -0.0013021548163800745"/>
      <mass value="49.95763546704962"/>
      <inertia ixx="0.204286" ixy="0.014389" ixz="0.00517" iyy="0.370215" iyz="-0.00385" izz="0.398271"/>
    </inertial>
    <visual>
      <origin rpy="0 0 0" xyz="-1.207 -0.102 -1.855"/>
      <geometry>
        <mesh filename="package://abb_irb6620_support/meshes/link5_1.stl" scale="0.001 0.001 0.001"/>
      </geometry>
      <material name="opaque215215215"/>
    </visual>
    <collision>
      <origin rpy="0 0 0" xyz="-1.207 -0.102 -1.855"/>
      <geometry>
        <mesh filename="package://abb_irb6620_support/meshes/link5_1.stl" scale="0.001 0.001 0.001"/>
      </geometry>
    </collision>
  </link>
  <link name="link6_1">
    <inertial>
      <origin rpy="0 0 0" xyz="0.013682763984402824 0.0004916127782434797 -8.489689701751679e-05"/>
      <mass value="7.203563041480472"/>
      <inertia ixx="0.037108" ixy="8e-06" ixz="1e-06" iyy="0.019368" iyz="-7e-05" izz="0.019147"/>
    </inertial>
    <visual>
      <origin rpy="0 0 0" xyz="-1.375 0.0 -1.855"/>
      <geometry>
        <mesh filename="package://abb_irb6620_support/meshes/link6_1.stl" scale="0.001 0.001 0.001"/>
      </geometry>
      <material name="opaque128128128"/>
    </visual>
    <collision>
      <origin rpy="0 0 0" xyz="-1.375 0.0 -1.855"/>
      <geometry>
        <mesh filename="package://abb_irb6620_support/meshes/link6_1.stl" scale="0.001 0.001 0.001"/>
      </geometry>
    </collision>
  </link>
  <link name="link1_1">
    <inertial>
      <origin rpy="0 0 0" xyz="0.14890152402063087 0.032537506095083685 0.29973883589665773"/>
      <mass value="642.4142354132725"/>
      <inertia ixx="27.786175" ixy="-2.179688" ixz="-12.883359" iyy="44.967832" iyz="-2.614551" izz="35.549494"/>
    </inertial>
    <visual>
      <origin rpy="0 0 0" xyz="-0.0 -0.0 -0.23"/>
      <geometry>
        <mesh filename="package://abb_irb6620_support/meshes/link1_1.stl" scale="0.001 0.001 0.001"/>
      </geometry>
      <material name="opaque215215215"/>
    </visual>
    <collision>
      <origin rpy="0 0 0" xyz="-0.0 -0.0 -0.23"/>
      <geometry>
        <mesh filename="package://abb_irb6620_support/meshes/link1_1.stl" scale="0.001 0.001 0.001"/>
      </geometry>
    </collision>
  </link>
  <joint name="joint_2" type="continuous">
    <origin rpy="0 0 0" xyz="0.32 -0.1305 0.45"/>
    <parent link="link1_1"/>
    <child link="link2_1"/>
    <axis xyz="-0.0 -1.0 -0.0"/>
  </joint>
  <joint name="joint_3" type="continuous">
    <origin rpy="0 0 0" xyz="0.0 -0.0955 0.975"/>
    <parent link="link2_1"/>
    <child link="link3_1"/>
    <axis xyz="0.0 -1.0 0.0"/>
  </joint>
  <joint name="joint_4" type="continuous">
    <origin rpy="0 0 0" xyz="0.182 0.226 0.2"/>
    <parent link="link3_1"/>
    <child link="link4_1"/>
    <axis xyz="1.0 0.0 0.0"/>
  </joint>
  <joint name="joint_5" type="continuous">
    <origin rpy="0 0 0" xyz="0.705 0.102 0.0"/>
    <parent link="link4_1"/>
    <child link="link5_1"/>
    <axis xyz="-0.0 -1.0 0.0"/>
  </joint>
  <joint name="joint_6" type="continuous">
    <origin rpy="0 0 0" xyz="0.168 -0.102 0.0"/>
    <parent link="link5_1"/>
    <child link="link6_1"/>
    <axis xyz="-1.0 0.0 0.0"/>
  </joint>
  <joint name="joint_1" type="continuous">
    <origin rpy="0 0 0" xyz="0.0 0.0 0.23"/>
    <parent link="base_link"/>
    <child link="link1_1"/>
    <axis xyz="0.0 0.0 1.0"/>
  </joint>

  <ros2_control name="ABBMultiInterfaceHardware" type="system">
    <hardware>
      <plugin>mock_components/GenericSystem</plugin>
      <param name="fake_sensor_commands">false</param>
      <param name="state_following_offset">0.0</param>
    </hardware>
    <joint name="joint_1">
      <command_interface name="position">
        <param name="min">-6.283185307179586</param>
        <param name="max">6.283185307179586</param>
      </command_interface>
      <command_interface name="velocity"/>
      <state_interface name="position">
        <param name="initial_value">0.0</param>
      </state_interface>
      <state_interface name="velocity"/>
    </joint>
    <joint name="joint_2">
      <command_interface name="position">
        <param name="min">-2.41</param>
        <param name="max">2.41</param>
      </command_interface>
      <command_interface name="velocity"/>
      <state_interface name="position">
        <param name="initial_value">0.0</param>
      </state_interface>
      <state_interface name="velocity"/>
    </joint>
    <joint name="joint_3">
      <command_interface name="position">
        <param name="min">-6.283185307179586</param>
        <param name="max">6.283185307179586</param>
      </command_interface>
      <command_interface name="velocity"/>
      <state_interface name="position">
        <param name="initial_value">0.0</param>
      </state_interface>
      <state_interface name="velocity"/>
    </joint>
    <joint name="joint_4">
      <command_interface name="position">
        <param name="min">-2.66</param>
        <param name="max">2.66</param>
      </command_interface>
      <command_interface name="velocity"/>
      <state_interface name="position">
        <param name="initial_value">0.0</param>
      </state_interface>
      <state_interface name="velocity"/>
    </joint>
    <joint name="joint_5">
      <command_interface name="position">
        <param name="min">-6.283185307179586</param>
        <param name="max">6.283185307179586</param>
      </command_interface>
      <command_interface name="velocity"/>
      <state_interface name="position">
        <param name="initial_value">0.0</param>
      </state_interface>
      <state_interface name="velocity"/>
    </joint>
    <joint name="joint_6">
      <command_interface name="position">
        <param name="min">-2.23</param>
        <param name="max">2.23</param>
      </command_interface>
      <command_interface name="velocity"/>
      <state_interface name="position">
        <param name="initial_value">0.0</param>
      </state_interface>
      <state_interface name="velocity"/>
    </joint>
  </ros2_control>
</robot>
