<?xml version="1.0" ?>
<robot name="dualarm_track" xmlns:xacro="http://www.ros.org/wiki/xacro">
  <xacro:arg name="use_fake_hardware" default="true"/>
  <xacro:property name="use_fake_hardware" value="$(arg use_fake_hardware)"/>
  <xacro:arg name="rws_ip" default="None"/>
  <xacro:property name="rws_ip" value="$(arg rws_ip)"/>
  <xacro:arg name="rws_port" default="80"/>
  <xacro:property name="rws_port" value="$(arg rws_port)"/>
  <xacro:arg name="configure_via_rws" default="true"/>
  <xacro:property name="configure_via_rws" value="$(arg configure_via_rws)"/>

  <xacro:include filename="$(find dualarm_track_support)/urdf/materials.xacro" />
  <!-- <xacro:include filename="$(find dualarm_track_support)/urdf/dualarm_track.trans" /> -->
  <link name="base_link">
    <inertial>
      <origin xyz="4.350000000000003 0.007802389093675564 0.22039220138139537" rpy="0 0 0"/>
      <mass value="17861.70571223475"/>
      <inertia ixx="874.507554" iyy="113200.027675" izz="113619.462683" ixy="-0.0" iyz="-17.225414" ixz="0.0"/>
    </inertial>
    <visual>
      <origin xyz="0 0 0" rpy="0 0 0"/>
      <geometry>
        <mesh filename="package://dualarm_track_support/meshes/base_link.stl" scale="0.001 0.001 0.001"/>
      </geometry>
      <material name="steel_satin"/>
    </visual>
    <collision>
      <origin xyz="0 0 0" rpy="0 0 0"/>
      <geometry>
        <mesh filename="package://dualarm_track_support/meshes/base_link.stl" scale="0.001 0.001 0.001"/>
      </geometry>
    </collision>
  </link>

  <link name="rob1_link2_1">
    <inertial>
      <origin xyz="-0.08783951896435793 -0.0005479770874912138 0.4192831405132833" rpy="0 0 0"/>
      <mass value="322.6869494051032"/>
      <inertia ixx="32.058389" iyy="31.332255" izz="2.725277" ixy="-0.002905" iyz="0.067522" ixz="2.969817"/>
    </inertial>
    <visual>
      <origin xyz="-0.3945 0.32 -1.158674" rpy="0 0 0"/>
      <geometry>
        <mesh filename="package://dualarm_track_support/meshes/rob1_link2_1.stl" scale="0.001 0.001 0.001"/>
      </geometry>
      <material name="opaque215215215"/>
    </visual>
    <collision>
      <origin xyz="-0.3945 0.32 -1.158674" rpy="0 0 0"/>
      <geometry>
        <mesh filename="package://dualarm_track_support/meshes/rob1_link2_1.stl" scale="0.001 0.001 0.001"/>
      </geometry>
    </collision>
  </link>

  <link name="rob1_link3_1">
    <inertial>
      <origin xyz="0.23437540848825827 0.04789961325356917 0.11779149410246958" rpy="0 0 0"/>
      <mass value="392.46903681876654"/>
      <inertia ixx="10.861718" iyy="11.726762" izz="11.751196" ixy="-1.465206" iyz="-1.592788" ixz="-2.045934"/>
    </inertial>
    <visual>
      <origin xyz="-0.299 0.32 -2.133674" rpy="0 0 0"/>
      <geometry>
        <mesh filename="package://dualarm_track_support/meshes/rob1_link3_1.stl" scale="0.001 0.001 0.001"/>
      </geometry>
      <material name="opaque215215215"/>
    </visual>
    <collision>
      <origin xyz="-0.299 0.32 -2.133674" rpy="0 0 0"/>
      <geometry>
        <mesh filename="package://dualarm_track_support/meshes/rob1_link3_1.stl" scale="0.001 0.001 0.001"/>
      </geometry>
    </collision>
  </link>

  <link name="rob1_link4_1">
    <inertial>
      <origin xyz="-0.014153009406352446 -0.3920696832791525 -6.094864964856228e-05" rpy="0 0 0"/>
      <mass value="283.78132224866226"/>
      <inertia ixx="11.46404" iyy="3.961577" izz="13.570946" ixy="-0.662055" iyz="0.007475" ixz="0.000528"/>
    </inertial>
    <visual>
      <origin xyz="-0.525 0.502 -2.333674" rpy="0 0 0"/>
      <geometry>
        <mesh filename="package://dualarm_track_support/meshes/rob1_link4_1.stl" scale="0.001 0.001 0.001"/>
      </geometry>
      <material name="opaque215215215"/>
    </visual>
    <collision>
      <origin xyz="-0.525 0.502 -2.333674" rpy="0 0 0"/>
      <geometry>
        <mesh filename="package://dualarm_track_support/meshes/rob1_link4_1.stl" scale="0.001 0.001 0.001"/>
      </geometry>
    </collision>
  </link>

  <link name="rob1_link5_1">
    <inertial>
      <origin xyz="-0.10016333880679884 -0.038074184295092905 -0.001302293522098541" rpy="0 0 0"/>
      <mass value="49.95763546704962"/>
      <inertia ixx="0.370215" iyy="0.204286" izz="0.398271" ixy="-0.014389" iyz="-0.00517" ixz="-0.00385"/>
    </inertial>
    <visual>
      <origin xyz="-0.627 1.207 -2.333674" rpy="0 0 0"/>
      <geometry>
        <mesh filename="package://dualarm_track_support/meshes/rob1_link5_1.stl" scale="0.001 0.001 0.001"/>
      </geometry>
      <material name="opaque215215215"/>
    </visual>
    <collision>
      <origin xyz="-0.627 1.207 -2.333674" rpy="0 0 0"/>
      <geometry>
        <mesh filename="package://dualarm_track_support/meshes/rob1_link5_1.stl" scale="0.001 0.001 0.001"/>
      </geometry>
    </collision>
  </link>

  <link name="rob1_link6_1">
    <inertial>
      <origin xyz="0.0004916127782503832 -0.013682763984406598 -8.503560273620536e-05" rpy="0 0 0"/>
      <mass value="7.203563041480472"/>
      <inertia ixx="0.019368" iyy="0.037108" izz="0.019147" ixy="-8e-06" iyz="-1e-06" ixz="-7e-05"/>
    </inertial>
    <visual>
      <origin xyz="-0.525 1.375 -2.333674" rpy="0 0 0"/>
      <geometry>
        <mesh filename="package://dualarm_track_support/meshes/rob1_link6_1.stl" scale="0.001 0.001 0.001"/>
      </geometry>
      <material name="opaque128128128"/>
    </visual>
    <collision>
      <origin xyz="-0.525 1.375 -2.333674" rpy="0 0 0"/>
      <geometry>
        <mesh filename="package://dualarm_track_support/meshes/rob1_link6_1.stl" scale="0.001 0.001 0.001"/>
      </geometry>
    </collision>
  </link>

  <link name="rob1_link1_1">
    <inertial>
      <origin xyz="0.03253750609511141 -0.1489015240206352 0.2997386971909384" rpy="0 0 0"/>
      <mass value="642.4142354132725"/>
      <inertia ixx="44.967832" iyy="27.786175" izz="35.549494" ixy="2.179688" iyz="12.883359" ixz="-2.614551"/>
    </inertial>
    <visual>
      <origin xyz="-0.525 0.0 -0.708674" rpy="0 0 0"/>
      <geometry>
        <mesh filename="package://dualarm_track_support/meshes/rob1_link1_1.stl" scale="0.001 0.001 0.001"/>
      </geometry>
      <material name="opaque215215215"/>
    </visual>
    <collision>
      <origin xyz="-0.525 0.0 -0.708674" rpy="0 0 0"/>
      <geometry>
        <mesh filename="package://dualarm_track_support/meshes/rob1_link1_1.stl" scale="0.001 0.001 0.001"/>
      </geometry>
    </collision>
  </link>

  <!-- <link name="rob2_link1_1">
    <inertial>
      <origin xyz="0.03253750609510231 -0.14890152402051815 0.2997386971909386" rpy="0 0 0"/>
      <mass value="642.4142354132725"/>
      <inertia ixx="44.967832" iyy="27.786175" izz="35.549494" ixy="2.179688" iyz="12.883359" ixz="-2.614551"/>
    </inertial>
    <visual>
      <origin xyz="-5.025 -0.0 -0.708674" rpy="0 0 0"/>
      <geometry>
        <mesh filename="package://dualarm_track_support/meshes/rob2_link1_1.stl" scale="0.001 0.001 0.001"/>
      </geometry>
      <material name="opaque215215215"/>
    </visual>
    <collision>
      <origin xyz="-5.025 -0.0 -0.708674" rpy="0 0 0"/>
      <geometry>
        <mesh filename="package://dualarm_track_support/meshes/rob2_link1_1.stl" scale="0.001 0.001 0.001"/>
      </geometry>
    </collision>
  </link>

  <link name="rob2_link2_1">
    <inertial>
      <origin xyz="-0.08783951896436637 -0.0005479770873740852 0.4192831405132835" rpy="0 0 0"/>
      <mass value="322.6869494051032"/>
      <inertia ixx="32.058389" iyy="31.332255" izz="2.725277" ixy="-0.002905" iyz="0.067522" ixz="2.969817"/>
    </inertial>
    <visual>
      <origin xyz="-4.8945 0.32 -1.158674" rpy="0 0 0"/>
      <geometry>
        <mesh filename="package://dualarm_track_support/meshes/rob2_link2_1.stl" scale="0.001 0.001 0.001"/>
      </geometry>
      <material name="opaque215215215"/>
    </visual>
    <collision>
      <origin xyz="-4.8945 0.32 -1.158674" rpy="0 0 0"/>
      <geometry>
        <mesh filename="package://dualarm_track_support/meshes/rob2_link2_1.stl" scale="0.001 0.001 0.001"/>
      </geometry>
    </collision>
  </link>

  <link name="rob2_link3_1">
    <inertial>
      <origin xyz="0.23437540848824945 0.04789961325368636 0.11779149410246958" rpy="0 0 0"/>
      <mass value="392.46903681876654"/>
      <inertia ixx="10.861718" iyy="11.726762" izz="11.751196" ixy="-1.465206" iyz="-1.592788" ixz="-2.045934"/>
    </inertial>
    <visual>
      <origin xyz="-4.799 0.32 -2.133674" rpy="0 0 0"/>
      <geometry>
        <mesh filename="package://dualarm_track_support/meshes/rob2_link3_1.stl" scale="0.001 0.001 0.001"/>
      </geometry>
      <material name="opaque215215215"/>
    </visual>
    <collision>
      <origin xyz="-4.799 0.32 -2.133674" rpy="0 0 0"/>
      <geometry>
        <mesh filename="package://dualarm_track_support/meshes/rob2_link3_1.stl" scale="0.001 0.001 0.001"/>
      </geometry>
    </collision>
  </link>

  <link name="rob2_link4_1">
    <inertial>
      <origin xyz="-0.014153009406362216 -0.3920696832790356 -6.094864964856228e-05" rpy="0 0 0"/>
      <mass value="283.78132224866226"/>
      <inertia ixx="11.46404" iyy="3.961577" izz="13.570946" ixy="-0.662055" iyz="0.007475" ixz="0.000528"/>
    </inertial>
    <visual>
      <origin xyz="-5.025 0.502 -2.333674" rpy="0 0 0"/>
      <geometry>
        <mesh filename="package://dualarm_track_support/meshes/rob2_link4_1.stl" scale="0.001 0.001 0.001"/>
      </geometry>
      <material name="opaque215215215"/>
    </visual>
    <collision>
      <origin xyz="-5.025 0.502 -2.333674" rpy="0 0 0"/>
      <geometry>
        <mesh filename="package://dualarm_track_support/meshes/rob2_link4_1.stl" scale="0.001 0.001 0.001"/>
      </geometry>
    </collision>
  </link>

  <link name="rob2_link5_1">
    <inertial>
      <origin xyz="-0.10016333880680772 -0.03807418429497589 -0.001302293522098541" rpy="0 0 0"/>
      <mass value="49.95763546704962"/>
      <inertia ixx="0.370215" iyy="0.204286" izz="0.398271" ixy="-0.014389" iyz="-0.00517" ixz="-0.00385"/>
    </inertial>
    <visual>
      <origin xyz="-5.127 1.207 -2.333674" rpy="0 0 0"/>
      <geometry>
        <mesh filename="package://dualarm_track_support/meshes/rob2_link5_1.stl" scale="0.001 0.001 0.001"/>
      </geometry>
      <material name="opaque215215215"/>
    </visual>
    <collision>
      <origin xyz="-5.127 1.207 -2.333674" rpy="0 0 0"/>
      <geometry>
        <mesh filename="package://dualarm_track_support/meshes/rob2_link5_1.stl" scale="0.001 0.001 0.001"/>
      </geometry>
    </collision>
  </link>

  <link name="rob2_link6_1">
    <inertial>
      <origin xyz="0.0004916127782417234 -0.013682763984289359 -8.503560273620536e-05" rpy="0 0 0"/>
      <mass value="7.203563041480472"/>
      <inertia ixx="0.019368" iyy="0.037108" izz="0.019147" ixy="-8e-06" iyz="-1e-06" ixz="-7e-05"/>
    </inertial>
    <visual>
      <origin xyz="-5.025 1.375 -2.333674" rpy="0 0 0"/>
      <geometry>
        <mesh filename="package://dualarm_track_support/meshes/rob2_link6_1.stl" scale="0.001 0.001 0.001"/>
      </geometry>
      <material name="opaque128128128"/>
    </visual>
    <collision>
      <origin xyz="-5.025 1.375 -2.333674" rpy="0 0 0"/>
      <geometry>
        <mesh filename="package://dualarm_track_support/meshes/rob2_link6_1.stl" scale="0.001 0.001 0.001"/>
      </geometry>
    </collision>
  </link> -->

  <link name="rob1_base_1">
    <inertial>
      <origin xyz="0.5251461441795046 0.07516456043445498 0.06698451289427176" rpy="0 0 0"/>
      <mass value="1368.8196309737446"/>
      <inertia ixx="145.638764" iyy="98.236958" izz="202.449913" ixy="0.019464" iyz="-9.296485" ixz="-0.095943"/>
    </inertial>
    <visual>
      <origin xyz="0.0 0.0 -0.433674" rpy="0 0 0"/>
      <geometry>
        <mesh filename="package://dualarm_track_support/meshes/rob1_base_1.stl" scale="0.001 0.001 0.001"/>
      </geometry>
      <material name="opaque215215215"/>
    </visual>
    <collision>
      <origin xyz="0.0 0.0 -0.433674" rpy="0 0 0"/>
      <geometry>
        <mesh filename="package://dualarm_track_support/meshes/rob1_base_1.stl" scale="0.001 0.001 0.001"/>
      </geometry>
    </collision>
  </link>

  <!-- <link name="rob2_base_1">
    <inertial>
      <origin xyz="5.025146144179496 0.07516456043457193 0.06698451289427176" rpy="0 0 0"/>
      <mass value="1368.8196309737452"/>
      <inertia ixx="145.638764" iyy="98.236958" izz="202.449913" ixy="0.019464" iyz="-9.296485" ixz="-0.095943"/>
    </inertial>
    <visual>
      <origin xyz="0.0 0.0 -0.433674" rpy="0 0 0"/>
      <geometry>
        <mesh filename="package://dualarm_track_support/meshes/rob2_base_1.stl" scale="0.001 0.001 0.001"/>
      </geometry>
      <material name="opaque215215215"/>
    </visual>
    <collision>
      <origin xyz="0.0 0.0 -0.433674" rpy="0 0 0"/>
      <geometry>
        <mesh filename="package://dualarm_track_support/meshes/rob2_base_1.stl" scale="0.001 0.001 0.001"/>
      </geometry>
    </collision>
  </link> -->

  <joint name="rob1_joint2" type="continuous">
    <origin xyz="-0.1305 -0.32 0.45" rpy="0 0 0"/>
    <parent link="rob1_link1_1"/>
    <child link="rob1_link2_1"/>
    <axis xyz="-1.0 0.0 0.0"/>
  </joint>

  <joint name="rob1_joint3" type="continuous">
    <origin xyz="-0.0955 0.0 0.975" rpy="0 0 0"/>
    <parent link="rob1_link2_1"/>
    <child link="rob1_link3_1"/>
    <axis xyz="-1.0 0.0 0.0"/>
  </joint>

  <joint name="rob1_joint4" type="continuous">
    <origin xyz="0.226 -0.182 0.2" rpy="0 0 0"/>
    <parent link="rob1_link3_1"/>
    <child link="rob1_link4_1"/>
    <axis xyz="-0.0 -1.0 -0.0"/>
  </joint>

  <joint name="rob1_joint5" type="continuous">
    <origin xyz="0.102 -0.705 0.0" rpy="0 0 0"/>
    <parent link="rob1_link4_1"/>
    <child link="rob1_link5_1"/>
    <axis xyz="-1.0 0.0 0.0"/>
  </joint>

  <joint name="rob1_joint6" type="continuous">
    <origin xyz="-0.102 -0.168 0.0" rpy="0 0 0"/>
    <parent link="rob1_link5_1"/>
    <child link="rob1_link6_1"/>
    <axis xyz="0.0 1.0 0.0"/>
  </joint>

  <joint name="rob1_joint1" type="continuous">
    <origin xyz="0.525 0.0 0.275" rpy="0 0 0"/>
    <parent link="rob1_base_1"/>
    <child link="rob1_link1_1"/>
    <axis xyz="0.0 -0.0 1.0"/>
  </joint>

  <!-- <joint name="rob2_joint1" type="continuous">
    <origin xyz="5.025 0.0 0.275" rpy="0 0 0"/>
    <parent link="rob2_base_1"/>
    <child link="rob2_link1_1"/>
    <axis xyz="0.0 0.0 1.0"/>
  </joint>

  <joint name="rob2_joint2" type="continuous">
    <origin xyz="-0.1305 -0.32 0.45" rpy="0 0 0"/>
    <parent link="rob2_link1_1"/>
    <child link="rob2_link2_1"/>
    <axis xyz="-1.0 0.0 0.0"/>
  </joint>

  <joint name="rob2_joint3" type="continuous">
    <origin xyz="-0.0955 0.0 0.975" rpy="0 0 0"/>
    <parent link="rob2_link2_1"/>
    <child link="rob2_link3_1"/>
    <axis xyz="1.0 -0.0 0.0"/>
  </joint>

  <joint name="rob2_joint4" type="continuous">
    <origin xyz="0.226 -0.182 0.2" rpy="0 0 0"/>
    <parent link="rob2_link3_1"/>
    <child link="rob2_link4_1"/>
    <axis xyz="-0.0 -1.0 0.0"/>
  </joint>

  <joint name="rob2_joint5" type="continuous">
    <origin xyz="0.102 -0.705 0.0" rpy="0 0 0"/>
    <parent link="rob2_link4_1"/>
    <child link="rob2_link5_1"/>
    <axis xyz="-1.0 0.0 -0.0"/>
  </joint>

  <joint name="rob2_joint6" type="continuous">
    <origin xyz="-0.102 -0.168 0.0" rpy="0 0 0"/>
    <parent link="rob2_link5_1"/>
    <child link="rob2_link6_1"/>
    <axis xyz="-0.0 -1.0 -0.0"/>
  </joint> -->

  <joint name="rob1_track" type="prismatic">
    <origin xyz="0.0 0.0 0.433674" rpy="0 0 0"/>
    <parent link="base_link"/>
    <child link="rob1_base_1"/>
    <axis xyz="1.0 0.0 0.0"/>
    <limit upper="3.5" lower="0.0" effort="100" velocity="100"/>
  </joint>

  <!-- <joint name="rob2_track" type="prismatic">
    <origin xyz="0.0 0.0 0.433674" rpy="0 0 0"/>
    <parent link="base_link"/>
    <child link="rob2_base_1"/>
    <axis xyz="1.0 0.0 0.0"/>
    <limit upper="7.5" lower="4.5" effort="100" velocity="100"/>
  </joint> -->


  <!-- rob1 ros2_control -->
    <xacro:include filename="$(find dualarm_track_support)/urdf/dualarm_track1.ros2_control.xacro" />
    <xacro:abb_ros2_control
      name="ABBMultiInterfaceHardware"
      prefix=""
      use_fake_hardware="${use_fake_hardware}"
      rws_ip="${rws_ip}"
      rws_port="${rws_port}"
      configure_via_rws="${configure_via_rws}"/>

  <!-- rob2 ros2_control -->
    <!-- <xacro:include filename="$(find dualarm_track_support)/urdf/dualarm_track2.ros2_control.xacro" />
    <xacro:abb_ros2_control
      name="ABBMultiInterfaceHardware"
      prefix=""
      use_fake_hardware="${use_fake_hardware}"
      rws_ip="${rws_ip}"
      rws_port="${rws_port}"
      configure_via_rws="${configure_via_rws}"/> -->
</robot>
